Workbook

Sheet Resumo
A1: Resumo por classe
A2: Valores com BDI, calculados a partir da aba "Curva ABC".
A4: Classe | B4: Linhas | C4: Valor (R$) | D4: % | E4: Δ BDI (R$)
A5: A | B5: =COUNTIF('Curva ABC'!$A$5:$A$81,A5) -> 19 | C5: =SUMIF('Curva ABC'!$A$5:$A$81,A5,'Curva ABC'!$G$5:$G$81) -> 631986.26 | D5: =C5/$C$8 -> 0.81157144 | E5: =SUMIF('Curva ABC'!$A$5:$A$81,A5,'Curva ABC'!$K$5:$K$81) -> -23632.54
A6: B | B6: =COUNTIF('Curva ABC'!$A$5:$A$81,A6) -> 20 | C6: =SUMIF('Curva ABC'!$A$5:$A$81,A6,'Curva ABC'!$G$5:$G$81) -> 109648.24 | D6: =C6/$C$8 -> 0.14080588 | E6: =SUMIF('Curva ABC'!$A$5:$A$81,A6,'Curva ABC'!$K$5:$K$81) -> -904.83
A7: C | B7: =COUNTIF('Curva ABC'!$A$5:$A$81,A7) -> 38 | C7: =SUMIF('Curva ABC'!$A$5:$A$81,A7,'Curva ABC'!$G$5:$G$81) -> 37084.7 | D7: =C7/$C$8 -> 0.047622686 | E7: =SUMIF('Curva ABC'!$A$5:$A$81,A7,'Curva ABC'!$K$5:$K$81) -> -418.59
A8: Total | B8: =SUM(B5:B7) -> 77 | C8: =SUM(C5:C7) -> 778719.2 | D8: =SUM(D5:D7) -> 1 | E8: =SUM(E5:E7) -> -24955.96
A10: Valores de controle (tabela do usuário): A 631.986,26 · B 109.648,24 · C 37.084,70 · Total 778.719,20 · Δ BDI −24.955,96.
A12: Valor por fonte do preço
A13: Fonte | B13: Linhas | C13: Valor (R$) | D13: %
A14: SINAPI | B14: =COUNTIF('Curva ABC'!$M$5:$M$81,A14) -> 36 | C14: =SUMIF('Curva ABC'!$M$5:$M$81,A14,'Curva ABC'!$G$5:$G$81) -> 79608.58 | D14: =C14/$C$22 -> 0.10223015
A15: SINAPI sem custo | B15: =COUNTIF('Curva ABC'!$M$5:$M$81,A15) -> 1 | C15: =SUMIF('Curva ABC'!$M$5:$M$81,A15,'Curva ABC'!$G$5:$G$81) -> 47892 | D15: =C15/$C$22 -> 0.061500988
A16: SEDOP | B16: =COUNTIF('Curva ABC'!$M$5:$M$81,A16) -> 2 | C16: =SUMIF('Curva ABC'!$M$5:$M$81,A16,'Curva ABC'!$G$5:$G$81) -> 9093.33 | D16: =C16/$C$22 -> 0.01167729
A17: ORSE | B17: =COUNTIF('Curva ABC'!$M$5:$M$81,A17) -> 2 | C17: =SUMIF('Curva ABC'!$M$5:$M$81,A17,'Curva ABC'!$G$5:$G$81) -> 338.55 | D17: =C17/$C$22 -> 0.00043475235
A18: EMBASA | B18: =COUNTIF('Curva ABC'!$M$5:$M$81,A18) -> 1 | C18: =SUMIF('Curva ABC'!$M$5:$M$81,A18,'Curva ABC'!$G$5:$G$81) -> 25370.35 | D18: =C18/$C$22 -> 0.032579587
A19: Cotação Biomais | B19: =COUNTIF('Curva ABC'!$M$5:$M$81,A19) -> 19 | C19: =SUMIF('Curva ABC'!$M$5:$M$81,A19,'Curva ABC'!$G$5:$G$81) -> 493404.28 | D19: =C19/$C$22 -> 0.63361001
A20: Cotação | B20: =COUNTIF('Curva ABC'!$M$5:$M$81,A20) -> 11 | C20: =SUMIF('Curva ABC'!$M$5:$M$81,A20,'Curva ABC'!$G$5:$G$81) -> 108797.46 | D20: =C20/$C$22 -> 0.13971334
A21: Composição própria | B21: =COUNTIF('Curva ABC'!$M$5:$M$81,A21) -> 5 | C21: =SUMIF('Curva ABC'!$M$5:$M$81,A21,'Curva ABC'!$G$5:$G$81) -> 14214.65 | D21: =C21/$C$22 -> 0.018253884
A22: Total | B22: =SUM(B14:B21) -> 77 | C22: =SUM(C14:C21) -> 778719.2 | D22: =SUM(D14:D21) -> 1
A23: Linhas agrupadas contam uma vez (ex.: 12.4.1 + 12.4.2). "SINAPI" inclui o 10.11, composição própria com o custo do SINAPI 94493.

Sheet Curva ABC
A1: Curva ABC corrigida: itens de engenharia mecânica (aba PLANILHA ORÇAMENTÁRIA)
A2: Obra: ETE do Hospital Barros Barreto (Belém/PA) · Orçamentista: Sanigy · Data-base 06/2025 · SINAPI-PA desonerado · Escopo: 80 itens mecânicos, agrupados em 77 linhas
A4: Classe | B4: # | C4: Item | D4: Linha | E4: Descrição | F4: Qtd | G4: R$ c/ BDI | H4: % do total | I4: % acum. | J4: BDI | K4: Δ BDI (R$) | L4: Verificar (bloco) e status | M4: Fonte do preço | N4: Código / evidência | O4: Situação do preço na fonte
A5: A | B5: 1 | C5: 12.4.1 + 12.4.2 | D5: 255 e 256 | E5: Decantador secundário 4,00 × 4,10 m + frete | F5: 2 + 2 | G5: 215671.4 | H5: =G5/$G$82 -> 0.27695657 | I5: =SUM($G$5:G5)/$G$82 -> 0.27695657 | J5: S → A | K5: -19178.68 | L5: Bloco F: proposta única; linha sem especificação (lamelas, internos); montagem do decantador não consta; BDI → aquisição (equipamento −R$ 17.932,38; frete −R$ 1.246,30); pedir cotação de transporte (AET) | M5: Cotação Biomais | N5: — | O5: Proposta única de 24/07/2025 (só a pág. 4, image36.png), sem CNPJ, validade ou especificação
A6: A | B6: 2 | C6: 6.1 + 6.2 | D6: 69 e 70 | E6: Guindaste 75 t (horas produtivas + improdutivas) | F6: 240 h + 480 h | G6: 47892 | H6: =G6/$G$82 -> 0.061500988 | I6: =SUM($G$5:G6)/$G$82 -> 0.33845756 | J6: S | L6: Bloco B: NÃO OK; sem custo oficial (hora = combustível + operador, sem a máquina); 720 h sem plano de içamento; falta mobilização do guindaste | M6: SINAPI sem custo | N6: 102850 / 102851 | O6: Código "sem custo" desde 11/2021; a planilha recompôs a hora só com materiais (102849) + operador (88296)
A7: A | B7: 3 | C7: 12.1.3 | D7: 236 | E7: Revestimento e reforço interno (UASB) | F7: 2 | G7: 33609.38 | H7: =G7/$G$82 -> 0.043159819 | I7: =SUM($G$5:G7)/$G$82 -> 0.38161738 | J7: S | L7: Bloco F: unidade nova ou existente? base em m² | M7: Cotação Biomais | N7: — | O7: Proposta única de 24/07/2025 (só a pág. 4, image36.png), sem CNPJ, validade ou especificação
A8: A | B8: 4 | C8: 10.4 | D8: 208 | E8: Difusor 250 mm | F8: 140 | G8: 30354.8 | H8: =G8/$G$82 -> 0.038980418 | I8: =SUM($G$5:G8)/$G$82 -> 0.4205978 | J8: A | L8: Bloco E: preço OK; 140 fecha com a rede | M8: Cotação | N8: Print de loja + mão de obra | O8: Difusor R$ 161,20 (cotação); mão de obra ≈ R$ 25,58, provável 0,5 h de 88267 + 0,5 h de 88248 (a confirmar na CPU)
A9: A | B9: 5 | C9: 12.1.6 | D9: 239 | E9: Montagem do sistema (UASB) | F9: 2 | G9: 29576.26 | H9: =G9/$G$82 -> 0.037980648 | I9: =SUM($G$5:G9)/$G$82 -> 0.45857845 | J9: S | L9: Bloco F: pode repetir o revestimento | M9: Cotação Biomais | N9: — | O9: Proposta única de 24/07/2025 (só a pág. 4, image36.png), sem CNPJ, validade ou especificação
A10: A | B10: 6 | C10: 12.2.1 | D10: 242 | E10: Revestimento e reforço interno (FBAS) | F10: 2 | G10: 29576.26 | H10: =G10/$G$82 -> 0.037980648 | I10: =SUM($G$5:G10)/$G$82 -> 0.49655909 | J10: S | L10: Bloco F: base de cálculo vs 12.1.3 | M10: Cotação Biomais | N10: — | O10: Proposta única de 24/07/2025 (só a pág. 4, image36.png), sem CNPJ, validade ou especificação
A11: A | B11: 7 | C11: 12.1.1 | D11: 234 | E11: Separador trifásico | F11: 2 | G11: 25886.62 | H11: =G11/$G$82 -> 0.03324256 | I11: =SUM($G$5:G11)/$G$82 -> 0.52980165 | J11: S → A | K11: -2301.98 | L11: Bloco F: escopo da proposta; BDI → aquisição | M11: Cotação Biomais | N11: — | O11: Proposta única de 24/07/2025 (só a pág. 4, image36.png), sem CNPJ, validade ou especificação
A12: A | B12: 8 | C12: 1.13 | D12: 28 | E12: Comissionamento da ETE (EMBASA) | F12: 1 | G12: 25370.35 | H12: =G12/$G$82 -> 0.032579587 | I12: =SUM($G$5:G12)/$G$82 -> 0.56238124 | J12: S | L12: Bloco A: NÃO VERIFICÁVEL; EMBASA/BA; sobreposição com guindaste | M12: EMBASA | N12: 41.05.01 | O12: Tabela EMBASA/BA não disponível; mesmo código na planilha do projetista (R$ 38.386,51)
A13: A | B13: 9 | C13: 10.3 | D13: 207 | E13: Soprador radial duplo estágio | F13: 2 | G13: 24987.56 | H13: =G13/$G$82 -> 0.032088024 | I13: =SUM($G$5:G13)/$G$82 -> 0.59446926 | J13: A | L13: Bloco E: NÃO VERIFICÁVEL; especificação em 3 versões | M13: Cotação | N13: Print Policomp JQT-7500 (image7.png) | O13: Especificação em 3 versões (item, CPU e print)
A14: A | B14: 10 | C14: 12.1.2 | D14: 235 | E14: Defletor em PRFV | F14: 2 | G14: 24198.74 | H14: =G14/$G$82 -> 0.031075052 | I14: =SUM($G$5:G14)/$G$82 -> 0.62554432 | J14: S → A | K14: -2151.88 | L14: Bloco F: escopo da proposta; BDI → aquisição | M14: Cotação Biomais | N14: — | O14: Proposta única de 24/07/2025 (só a pág. 4, image36.png), sem CNPJ, validade ou especificação
A15: A | B15: 11 | C15: 12.2.4 | D15: 245 | E15: Montagem do sistema (FBAS) | F15: 2 | G15: 24198.74 | H15: =G15/$G$82 -> 0.031075052 | I15: =SUM($G$5:G15)/$G$82 -> 0.65661937 | J15: S | L15: Bloco F: pode repetir o revestimento | M15: Cotação Biomais | N15: — | O15: Proposta única de 24/07/2025 (só a pág. 4, image36.png), sem CNPJ, validade ou especificação
A16: A | B16: 12 | C16: 10.8 | D16: 212 | E16: Pall ring 2" | F16: 15 m³ | G16: 21270.15 | H16: =G16/$G$82 -> 0.027314275 | I16: =SUM($G$5:G16)/$G$82 -> 0.68393364 | J16: A | L16: Bloco E: OK com ressalva; 2" × 3"; conferir volume | M16: Cotação | N16: Print de loja | O16: R$ 1.180,00/m³ (cotação "2"")
A17: A | B17: 13 | C17: 12.1.5 | D17: 238 | E17: Substituição do acesso lateral e superior (UASB) | F17: 2 | G17: 17476.88 | H17: =G17/$G$82 -> 0.022443109 | I17: =SUM($G$5:G17)/$G$82 -> 0.70637675 | J17: S | L17: Bloco F: reforma de unidade existente? | M17: Cotação Biomais | N17: — | O17: Proposta única de 24/07/2025 (só a pág. 4, image36.png), sem CNPJ, validade ou especificação
A18: A | B18: 14 | C18: 12.1.4 | D18: 237 | E18: Pintura com gelcoat (UASB) | F18: 2 | G18: 16132.5 | H18: =G18/$G$82 -> 0.02071671 | I18: =SUM($G$5:G18)/$G$82 -> 0.72709346 | J18: S | L18: Bloco F: escopo da proposta | M18: Cotação Biomais | N18: — | O18: Proposta única de 24/07/2025 (só a pág. 4, image36.png), sem CNPJ, validade ou especificação
A19: A | B19: 15 | C19: 12.3.2 | D19: 249 | E19: Revestimento e reforço interno (tanque de contato) | F19: 2 | G19: 16132.5 | H19: =G19/$G$82 -> 0.02071671 | I19: =SUM($G$5:G19)/$G$82 -> 0.74781017 | J19: S | L19: Bloco F: base de cálculo | M19: Cotação Biomais | N19: — | O19: Proposta única de 24/07/2025 (só a pág. 4, image36.png), sem CNPJ, validade ou especificação
A20: A | B20: 16 | C20: 12.3.5 | D20: 252 | E20: Montagem do sistema (tanque de contato) | F20: 2 | G20: 13443.74 | H20: =G20/$G$82 -> 0.017263912 | I20: =SUM($G$5:G20)/$G$82 -> 0.76507409 | J20: S | L20: Bloco F: pode repetir o revestimento | M20: Cotação Biomais | N20: — | O20: Proposta única de 24/07/2025 (só a pág. 4, image36.png), sem CNPJ, validade ou especificação
A21: A | B21: 17 | C21: 8.2.14 | D21: 108 | E21: Tê de redução 75 × 50 | F21: 140 | G21: 13400.8 | H21: =G21/$G$82 -> 0.017208771 | I21: =SUM($G$5:G21)/$G$82 -> 0.78228286 | J21: S | L21: Bloco C: 140 = difusores; sem tubo DN 50; ≈ 2,6 saídas/m | M21: SINAPI | N21: 94698 | O21: Igual à tabela SINAPI-PA 06/2025 ao centavo
A22: A | B22: 18 | C22: 10.7 | D22: 211 | E22: Motobomba submersível Brava E30 | F22: 2 | G22: 13396.96 | H22: =G22/$G$82 -> 0.017203839 | I22: =SUM($G$5:G22)/$G$82 -> 0.7994867 | J22: A | L22: Bloco E: preço OK; função e ponto de operação | M22: Cotação | N22: Print de loja | O22: Motobomba Brava E30, R$ 5.679,24
A23: A | B23: 19 | C23: 12.2.2 | D23: 243 | E23: Pintura com gelcoat (FBAS) | F23: 2 | G23: 9410.62 | H23: =G23/$G$82 -> 0.012084741 | I23: =SUM($G$5:G23)/$G$82 -> 0.81157144 | J23: S | L23: Bloco F: escopo da proposta | M23: Cotação Biomais | N23: — | O23: Proposta única de 24/07/2025 (só a pág. 4, image36.png), sem CNPJ, validade ou especificação
A24: B | B24: 20 | C24: 12.2.3 | D24: 244 | E24: Substituição do acesso superior (FBAS) | F24: 2 | G24: 8738.44 | H24: =G24/$G$82 -> 0.011221555 | I24: =SUM($G$5:G24)/$G$82 -> 0.82279299 | J24: S | L24: Bloco F: escopo da proposta | M24: Cotação Biomais | N24: — | O24: Proposta única de 24/07/2025 (só a pág. 4, image36.png), sem CNPJ, validade ou especificação
A25: B | B25: 21 | C25: 12.3.4 | D25: 251 | E25: Substituição do acesso superior (tanque de contato) | F25: 2 | G25: 8738.44 | H25: =G25/$G$82 -> 0.011221555 | I25: =SUM($G$5:G25)/$G$82 -> 0.83401455 | J25: S | L25: Bloco F: escopo da proposta | M25: Cotação Biomais | N25: — | O25: Proposta única de 24/07/2025 (só a pág. 4, image36.png), sem CNPJ, validade ou especificação
A26: B | B26: 22 | C26: 12.3.1 | D26: 248 | E26: Kit chincana | F26: 2 | G26: 8263.86 | H26: =G26/$G$82 -> 0.010612118 | I26: =SUM($G$5:G26)/$G$82 -> 0.84462666 | J26: S → A | K26: -734.88 | L26: Bloco F: fornecimento sem montagem; BDI → aquisição | M26: Cotação Biomais | N26: — | O26: Proposta única de 24/07/2025 (só a pág. 4, image36.png), sem CNPJ, validade ou especificação
A27: B | B27: 23 | C27: 1.16 | D27: 31 | E27: Comissionamento do combate a incêndio | F27: 1 | G27: 8043.13 | H27: =G27/$G$82 -> 0.010328665 | I27: =SUM($G$5:G27)/$G$82 -> 0.85495533 | J27: S | L27: Bloco A: NÃO OK; excluir ou reduzir | M27: Composição própria | N27: Composição 29 (projetista) | O27: 40 h eng. júnior 90777 + 40 h encanador 88267 + 20 h auxiliar 88248 (SINAPI)
A28: B | B28: 24 | C28: 10.10 | D28: 214 | E28: Registro de gaveta 4" | F28: 3 | G28: 7719.81 | H28: =G28/$G$82 -> 0.0099134707 | I28: =SUM($G$5:G28)/$G$82 -> 0.8648688 | J28: S | L28: Bloco E: SEDOP, NÃO VERIFICÁVEL; flange ou rosca? | M28: SEDOP | N28: 180801 | O28: "Registro de gaveta 4" - bruto"; tabela SEDOP não disponível
A29: B | B29: 25 | C29: 8.2.6 | D29: 100 | E29: Tubo PVC DN 110 | F29: 39 m | G29: 6998.55 | H29: =G29/$G$82 -> 0.0089872575 | I29: =SUM($G$5:G29)/$G$82 -> 0.87385606 | J29: S | L29: Bloco C: preço OK; temperatura do ar × PVC | M29: SINAPI | N29: 94655 | O29: Igual à tabela SINAPI-PA 06/2025 ao centavo
A30: B | B30: 26 | C30: 10.1 | D30: 205 | E30: Calha Parshall 6" | F30: 1 | G30: 6902.11 | H30: =G30/$G$82 -> 0.0088634132 | I30: =SUM($G$5:G30)/$G$82 -> 0.88271947 | J30: A | L30: Bloco E: OK com ressalva; cotação inclui caixas | M30: Cotação | N30: Print Bakof (image5.png) | O30: R$ 5.883,02, com caixas de entrada e saída
A31: B | B31: 27 | C31: 8.3.1 | D31: 122 | E31: Tubo aço galvanizado DN 80 | F31: 34 m | G31: 6742.54 | H31: =G31/$G$82 -> 0.0086584998 | I31: =SUM($G$5:G31)/$G$82 -> 0.89137797 | J31: S | L31: Bloco D: NÃO OK; conexões são 2½" | M31: SINAPI | N31: 94464 | O31: Igual à tabela SINAPI-PA 06/2025 ao centavo
A32: B | B32: 28 | C32: 8.2.23 | D32: 117 | E32: Adaptador com flanges DN 110 × 4" | F32: 14 | G32: 6191.78 | H32: =G32/$G$82 -> 0.0079512358 | I32: =SUM($G$5:G32)/$G$82 -> 0.89932921 | J32: S | L32: Bloco C: 14 = 2×(3+4) coerente; tipo de conexão | M32: SINAPI | N32: 94715 | O32: Igual à tabela SINAPI-PA 06/2025 ao centavo
A33: B | B33: 29 | C33: 8.2.19 | D33: 113 | E33: União PVC DN 110 (Tigre) | F33: 8 | G33: 4871.44 | H33: =G33/$G$82 -> 0.0062557081 | I33: =SUM($G$5:G33)/$G$82 -> 0.90558491 | J33: S | L33: Bloco C: por que 8? marca Tigre | M33: Composição própria | N33: Composição 4 (projetista) | O33: Insumo SINAPI 9908 (união 110 mm) + mão de obra SINAPI; descrição com marca "Tigre"
A34: B | B34: 30 | C34: 12.3.3 | D34: 250 | E34: Pintura com gelcoat (tanque de contato) | F34: 2 | G34: 4705.3 | H34: =G34/$G$82 -> 0.0060423578 | I34: =SUM($G$5:G34)/$G$82 -> 0.91162727 | J34: S | L34: Bloco F: escopo da proposta | M34: Cotação Biomais | N34: — | O34: Proposta única de 24/07/2025 (só a pág. 4, image36.png), sem CNPJ, validade ou especificação
A35: B | B35: 31 | C35: 10.5 | D35: 209 | E35: Filtro de entrada | F35: 2 | G35: 4132.98 | H35: =G35/$G$82 -> 0.0053074073 | I35: =SUM($G$5:G35)/$G$82 -> 0.91693468 | J35: A | L35: Bloco E: NÃO OK; filtro 2" × soprador | M35: Cotação | N35: Print de loja | O35: Filtro de 2" para até 5 m³/min
A36: B | B36: 32 | C36: 8.2.11 | D36: 105 | E36: Joelho 90° DN 110 | F36: 11 | G36: 4084.19 | H36: =G36/$G$82 -> 0.0052447532 | I36: =SUM($G$5:G36)/$G$82 -> 0.92217943 | J36: S | L36: Bloco C: conferir no isométrico | M36: SINAPI | N36: 94686 | O36: Igual à tabela SINAPI-PA 06/2025 ao centavo
A37: B | B37: 33 | C37: 12.3.6 | D37: 253 | E37: Frete do conjunto tanque de contato | F37: 2 | G37: 3822.3 | H37: =G37/$G$82 -> 0.0049084445 | I37: =SUM($G$5:G37)/$G$82 -> 0.92708788 | J37: S → A | K37: -169.95 | L37: Bloco F: NÃO OK; qtd 2 × proposta 1 (−R$ 1.911,15, à parte); BDI → aquisição | M37: Cotação Biomais | N37: — | O37: Proposta única de 24/07/2025 (só a pág. 4, image36.png), sem CNPJ, validade ou especificação
A38: B | B38: 34 | C38: 8.2.4 | D38: 98 | E38: Tubo PVC DN 75 | F38: 53 m | G38: 3818.65 | H38: =G38/$G$82 -> 0.0049037573 | I38: =SUM($G$5:G38)/$G$82 -> 0.93199163 | J38: S | L38: Bloco C: comprimento × planta | M38: SINAPI | N38: 89451 | O38: Igual à tabela SINAPI-PA 06/2025 ao centavo
A39: B | B39: 35 | C39: 8.2.10 | D39: 104 | E39: Joelho 90° DN 75 | F39: 24 | G39: 3658.08 | H39: =G39/$G$82 -> 0.0046975598 | I39: =SUM($G$5:G39)/$G$82 -> 0.93668919 | J39: S | L39: Bloco C: conferir no isométrico | M39: SINAPI | N39: 89513 | O39: Igual à tabela SINAPI-PA 06/2025 ao centavo
A40: B | B40: 36 | C40: 10.2 | D40: 206 | E40: Bomba dosadora EMEC FCE | F40: 2 | G40: 3299.14 | H40: =G40/$G$82 -> 0.0042366234 | I40: =SUM($G$5:G40)/$G$82 -> 0.94092582 | J40: A | L40: Bloco E: NÃO VERIFICÁVEL; pedir 3 propostas | M40: Cotação | N40: Print de loja | O40: Dosadora EMEC FCE, R$ 1.367,90
A41: B | B41: 37 | C41: 10.16 | D41: 220 | E41: Retenção horizontal 4" | F41: 2 | G41: 3144.44 | H41: =G41/$G$82 -> 0.0040379639 | I41: =SUM($G$5:G41)/$G$82 -> 0.94496378 | J41: S | L41: Bloco E: preço OK; 4 retenções p/ 2 bombas | M41: SINAPI | N41: 99626 | O41: Igual à tabela SINAPI-PA 06/2025 ao centavo
...

Sheet Legenda
A1: Legenda (três usos diferentes de letras)
A2: 1. Classe ABC | B2: Ordem de valor. A = até 80% do valor acumulado (inclui o item que cruza 80%); B = de 80% a 95%; C = de 95% a 100%.
A3: 2. Coluna "BDI" | B3: S = BDI de serviço (27,41%); A = BDI de aquisição (16,08%, mero fornecimento de equipamento ou material). "S → A" = a planilha aplicou S, mas o correto é A.
A4: 3. "Bloco A a G" | B4: Bloco do roteiro de verificação: A = comissionamento (1.13, 1.16) · B = içamento (6.1, 6.2) · C = rede PVC (8.2.x) · D = aço galvanizado (8.3.x) · E = equipamentos e válvulas (10.x) · F = PRFV (12.x) · G = incêndio (13.x).
A6: Outras colunas
A7: Item | B7: Número na planilha (com "+" quando duas linhas foram somadas por serem o mesmo objeto de custo).
A8: Linha | B8: Linha na aba PLANILHA ORÇAMENTÁRIA.
A9: R$ c/ BDI | B9: Coluna H da aba PLANILHA ORÇAMENTÁRIA.
A10: % acum. | B10: Percentual acumulado do valor (fórmula).
A11: Δ BDI | B11: Efeito de trocar o BDI aplicado pelo correto (negativo = redução; 12.3.6 usa quantidade 1).
A12: Status | B12: OK · OK com ressalva · NÃO OK (erro comprovado) · NÃO VERIFICÁVEL (falta documento ou fonte).
A13: Regra de agrupamento | B13: Só para a análise; a medição continua por linha. Soma linhas que são o mesmo objeto de custo (decantador + frete; guindaste produtivo + improdutivo; registro DN 60 de mesmo código). Não agrupa acessórios que são bens diferentes nem fretes de conjunto.
A15: Fonte do preço
A16: SINAPI | B16: Preço igual à tabela SINAPI-PA 06/2025 desonerada, ao centavo (verificado na sessão 1). O código foi identificado pelo preço e pela descrição e conferido com a planilha do projetista (mesmo código nas 36 linhas).
A17: SINAPI sem custo | B17: Código SINAPI que a CAIXA não precifica; o custo foi recomposto pelo orçamentista.
A18: SEDOP / ORSE / EMBASA | B18: Tabelas do Pará, de Sergipe e da Bahia. Não estavam disponíveis: preço não conferido. Códigos conferidos na planilha do projetista.
A19: Cotação Biomais | B19: Proposta única do fornecedor de PRFV (grupo 12).
A20: Cotação | B20: Composição própria cujo insumo principal vem de print de loja ou proposta (aba COTAÇÕES INICIAL).
A21: Composição própria | B21: Composição do orçamentista sem banco oficial identificado para o insumo principal.
A23: Cores | B23: Azul claro = classe A · amarelo = classe B · cinza = classe C · laranja nas colunas BDI e Δ BDI = "S → A".

Sheet Comparação projetista
A1: Comparação: planilha analisada (data-base 06/2025) × planilha do projetista (Sanigy, 23/02/2026)
A2: Projetista: arquivo "ORÇAMENTO ETE. BARROS BARRETO maio-2026 - entregue.xls", aba PLANILHA ORÇAMENTÁRIA; bases SINAPI 11/2025 desonerado, ORSE 05/2025, SEDOP 10/2025, SICRO3 07/2025 (nota da linha 324). Valores com BDI.
A4: # | B4: Item | C4: Descrição | D4: Qtd analisada | E4: Qtd projetista | F4: R$ analisada | G4: R$ projetista | H4: Diferença (R$) | I4: Diferença (%) | J4: Linha no projetista | K4: Fonte / código no projetista | L4: Observação
A5: 1 | B5: 12.4.1 + 12.4.2 | C5: Decantador secundário 4,00 × 4,10 m + frete | D5: 2 + 2 | E5: 2 + 2 | F5: 215671.4 | G5: 215671.4 | H5: =F5-G5 -> 0 | I5: =IF(G5=0,"",H5/G5) -> 0 | J5: 264 e 265 | K5: COTAÇÃO - / COTAÇÃO - | L5: Idêntico (mesma proposta Biomais e mesmo BDI de serviço)
A6: 2 | B6: 6.1 + 6.2 | C6: Guindaste 75 t (horas produtivas + improdutivas) | D6: 240 h + 480 h | E6: 240 + 480 | F6: 47892 | G6: 47824.8 | H6: =F6-G6 -> 67.2 | I6: =IF(G6=0,"",H6/G6) -> 0.0014051287 | J6: 66 e 67 | K6: SINAPI 102850 / SINAPI 102851 | L6: Mesmo código sem custo e mesma recomposição (materiais + operador); diferença de R$ 0,22/h nos materiais
A7: 3 | B7: 12.1.3 | C7: Revestimento e reforço interno (UASB) | D7: 2 | E7: 2 | F7: 33609.38 | G7: 33609.38 | H7: =F7-G7 -> 0 | I7: =IF(G7=0,"",H7/G7) -> 0 | J7: 242 | K7: COTAÇÃO - | L7: Idêntico (mesma proposta Biomais e mesmo BDI de serviço)
A8: 4 | B8: 10.4 | C8: Difusor 250 mm | D8: 140 | E8: 140 | F8: 30354.8 | G8: 26196.8 | H8: =F8-G8 -> 4158 | I8: =IF(G8=0,"",H8/G8) -> 0.15872168 | J8: 212 | K8: COTAÇÃO - | L8: Mesmo insumo cotado; a analisada soma mão de obra de instalação, a do projetista é só fornecimento
A9: 5 | B9: 12.1.6 | C9: Montagem do sistema (UASB) | D9: 2 | E9: 2 | F9: 29576.26 | G9: 29576.26 | H9: =F9-G9 -> 0 | I9: =IF(G9=0,"",H9/G9) -> 0 | J9: 245 | K9: COTAÇÃO - | L9: Idêntico (mesma proposta Biomais e mesmo BDI de serviço)
A10: 6 | B10: 12.2.1 | C10: Revestimento e reforço interno (FBAS) | D10: 2 | E10: 2 | F10: 29576.26 | G10: 29576.26 | H10: =F10-G10 -> 0 | I10: =IF(G10=0,"",H10/G10) -> 0 | J10: 249 | K10: COTAÇÃO - | L10: Idêntico (mesma proposta Biomais e mesmo BDI de serviço)
A11: 7 | B11: 12.1.1 | C11: Separador trifásico | D11: 2 | E11: 2 | F11: 25886.62 | G11: 25886.62 | H11: =F11-G11 -> 0 | I11: =IF(G11=0,"",H11/G11) -> 0 | J11: 240 | K11: COTAÇÃO - | L11: Idêntico (mesma proposta Biomais e mesmo BDI de serviço)
A12: 8 | B12: 1.13 | C12: Comissionamento da ETE (EMBASA) | D12: 1 | E12: 1 | F12: 25370.35 | G12: 38386.51 | H12: =F12-G12 -> -13016.16 | I12: =IF(G12=0,"",H12/G12) -> -0.33908162 | J12: 28 | K12: EMBASA 41.05.01 | L12: Mesmo código EMBASA; a analisada está 33,9% abaixo. Pedir as duas composições para explicar a diferença
A13: 9 | B13: 10.3 | C13: Soprador radial duplo estágio | D13: 2 | E13: 2 | F13: 24987.56 | G13: 24534.42 | H13: =F13-G13 -> 453.14 | I13: =IF(G13=0,"",H13/G13) -> 0.018469562 | J13: 211 | K13: COTAÇÃO - | L13: Mesmo insumo cotado; a analisada soma mão de obra de instalação, a do projetista é só fornecimento
A14: 10 | B14: 12.1.2 | C14: Defletor em PRFV | D14: 2 | E14: 2 | F14: 24198.74 | G14: 24198.74 | H14: =F14-G14 -> 0 | I14: =IF(G14=0,"",H14/G14) -> 0 | J14: 241 | K14: COTAÇÃO | L14: Idêntico (mesma proposta Biomais e mesmo BDI de serviço)
A15: 11 | B15: 12.2.4 | C15: Montagem do sistema (FBAS) | D15: 2 | E15: 2 | F15: 24198.74 | G15: 24198.74 | H15: =F15-G15 -> 0 | I15: =IF(G15=0,"",H15/G15) -> 0 | J15: 252 | K15: COTAÇÃO - | L15: Idêntico (mesma proposta Biomais e mesmo BDI de serviço)
A16: 12 | B16: 10.8 | C16: Pall ring 2" | D16: 15 m³ | E16: 15 | F16: 21270.15 | G16: 20546.1 | H16: =F16-G16 -> 724.05 | I16: =IF(G16=0,"",H16/G16) -> 0.035240265 | J16: 216 | K16: COTAÇÃO - | L16: Mesmo insumo cotado; a analisada soma mão de obra de instalação, a do projetista é só fornecimento
... A81: 77 | B81: 8.2.7 | C81: Joelho 90° DN 20 | D81: 1 | E81: 1 | F81: 9.61 | G81: 9.59 | H81: =F81-G81 -> 0.02 | I81: =IF(G81=0,"",H81/G81) -> 0.0020855057 | J81: 100 | K81: SINAPI 89404 | L81: Mesmo código; diferença = data-base do SINAPI (06/2025 na analisada × 11/2025 na do projetista)
C82: Total do escopo mecânico | F82: =SUM(F5:F81) -> 778719.2 | G82: =SUM(G5:G81) -> 786370.57 | H82: =F82-G82 -> -7651.37 | I82: =H82/G82 -> -0.0097299801
A84: Diferença positiva = a planilha analisada está acima da do projetista. Linhas em amarelo: diferenças que não são de data-base nem de mão de obra.
A85: Totais gerais (fora do escopo mecânico): analisada R$ 2.343.873,57 (HANDOFF, seção 3) × projetista R$ 1.892.034,82 (aba RESUMO). A diferença de R$ 451.838,75 está nos grupos não mecânicos e precisa da planilha analisada para ser localizada.
